Traceback (most recent call last):
  File "/usr/share/miniconda/envs/python-fortran/lib/python3.9/site-packages/jupyter_cache/executors/utils.py", line 58, in single_nb_execution
    executenb(
  File "/usr/share/miniconda/envs/python-fortran/lib/python3.9/site-packages/nbclient/client.py", line 1314, in execute
    return NotebookClient(nb=nb, resources=resources, km=km, **kwargs).execute()
  File "/usr/share/miniconda/envs/python-fortran/lib/python3.9/site-packages/jupyter_core/utils/__init__.py", line 165, in wrapped
    return loop.run_until_complete(inner)
  File "/usr/share/miniconda/envs/python-fortran/lib/python3.9/asyncio/base_events.py", line 647, in run_until_complete
    return future.result()
  File "/usr/share/miniconda/envs/python-fortran/lib/python3.9/site-packages/nbclient/client.py", line 709, in async_execute
    await self.async_execute_cell(
  File "/usr/share/miniconda/envs/python-fortran/lib/python3.9/site-packages/nbclient/client.py", line 1062, in async_execute_cell
    await self._check_raise_for_error(cell, cell_index, exec_reply)
  File "/usr/share/miniconda/envs/python-fortran/lib/python3.9/site-packages/nbclient/client.py", line 918, in _check_raise_for_error
    raise CellExecutionError.from_cell_and_msg(cell, exec_reply_content)
nbclient.exceptions.CellExecutionError: An error occurred while executing the following cell:
------------------
import _syracuseC

syracuse = _syracuseC.syracuse
syracuse(1000)
------------------


[0;31m---------------------------------------------------------------------------[0m
[0;31mModuleNotFoundError[0m                       Traceback (most recent call last)
Cell [0;32mIn[15], line 1[0m
[0;32m----> 1[0m [38;5;28;01mimport[39;00m [38;5;21;01m_syracuseC[39;00m
[1;32m      3[0m syracuse [38;5;241m=[39m _syracuseC[38;5;241m.[39msyracuse
[1;32m      4[0m syracuse([38;5;241m1000[39m)

[0;31mModuleNotFoundError[0m: No module named '_syracuseC'

